<?xml version="1.0" ?>
<sdf version="1.7">
  <model name="dienen_robot">

    <plugin name="navigation_plugin" filename="libdienen_navigation_plugin.so" />

    <link name="lower_body_link">
      <pose>0 0 0 0 0 0</pose>
      <inertial>
        <mass>10.0</mass>
      </inertial>
      <collision name="lower_body_collision">
        <geometry>
          <mesh>
            <uri>model://dienen_robot/collisions/lower_body_collision.dae</uri>
          </mesh>
        </geometry>
        <surface>
          <friction>
            <ode>
              <mu>10</mu>
              <mu2>10</mu2>
              <fdir1>0 0 0</fdir1>
              <slip1>0</slip1>
              <slip2>0</slip2>
            </ode>
          </friction>
        </surface>
      </collision>
      <visual name="lower_body_visual">
        <pose>0 0 0 0 0 0</pose>
        <geometry>
          <mesh>
            <uri>model://dienen_robot/meshes/lower_body.dae</uri>
          </mesh>
        </geometry>
      </visual>
    </link>

    <link name="upper_body_link">
      <pose>0 0 1.12161 0 0 0</pose>
      <inertial>
        <mass>10.0</mass>
      </inertial>
      <collision name="upper_body_collision">
        <geometry>
          <mesh>
            <uri>model://dienen_robot/collisions/upper_body_collision.dae</uri>
          </mesh>
        </geometry>
      </collision>
      <visual name="upper_body_visual">
        <geometry>
          <mesh>
            <uri>model://dienen_robot/meshes/upper_body.dae</uri>
          </mesh>
        </geometry>
      </visual>
    </link>

    <link name="depth_camera_link">
      <pose>0.10267 0 1.37778 0 0 0</pose>
      <inertial>
        <mass>10.0</mass>
      </inertial>
      <collision name="depth_camera_collision">
        <geometry>
          <mesh>
            <uri>model://dienen_robot/collisions/depth_camera_collision.dae</uri>
          </mesh>
        </geometry>
      </collision>
      <visual name="depth_camera_visual">
        <geometry>
          <mesh>
            <uri>model://dienen_robot/meshes/depth_camera.dae</uri>
          </mesh>
        </geometry>
      </visual>
      <sensor name="depth_camera" type="depth">
        <update_rate>30</update_rate>
        <plugin name="depth_camera_plugin" filename="libgazebo_ros_camera.so">
          <ros>
            <argument>/depth_camera/image_raw:=/rgb/image</argument>
            <argument>/depth_camera/camera_info:=/rgb/camera_info</argument>
            <argument>/depth_camera/depth/image_raw:=/depth/image</argument>
          </ros>
          <camera_name>depth_camera</camera_name>
          <hack_baseline>0.07</hack_baseline>
          <min_depth>0.001</min_depth>
        </plugin>
        <camera>
          <horizontal_fov>1.047198</horizontal_fov>
          <image>
            <width>640</width>
            <height>480</height>
            <format>R8G8B8</format>
          </image>
          <clip>
            <near>0.05</near>
            <far>30</far>
          </clip>
        </camera>
      </sensor>
    </link>

    <link name="neck_link">
      <pose>-0.018237 0 1.43554 0 0 0</pose>
      <inertial>
        <mass>10.0</mass>
      </inertial>
      <collision name="neck_collision">
        <geometry>
          <mesh>
            <uri>model://dienen_robot/collisions/neck_collision.dae</uri>
          </mesh>
        </geometry>
      </collision>
      <visual name="neck_visual">
        <geometry>
          <mesh>
            <uri>model://dienen_robot/meshes/neck.dae</uri>
          </mesh>
        </geometry>
      </visual>
    </link>

    <link name="head_link">
      <pose>-0.012258 0 1.46717 0 0 0</pose>
      <inertial>
        <mass>10.0</mass>
      </inertial>
      <collision name="head_collision">
        <geometry>
          <mesh>
            <uri>model://dienen_robot/collisions/head_collision.dae</uri>
          </mesh>
        </geometry>
      </collision>
      <visual name="head_visual">
        <geometry>
          <mesh>
            <uri>model://dienen_robot/meshes/head.dae</uri>
          </mesh>
        </geometry>
      </visual>
    </link>

    <link name="camera_link">
      <pose>0.049994 0 1.66776 0 0 0</pose>
      <inertial>
        <mass>10.0</mass>
      </inertial>
      <collision name="camera_collision">
        <geometry>
          <mesh>
            <uri>model://dienen_robot/collisions/camera_collision.dae</uri>
          </mesh>
        </geometry>
      </collision>
      <visual name="camera_visual">
        <geometry>
          <mesh>
            <uri>model://dienen_robot/meshes/camera.dae</uri>
          </mesh>
        </geometry>
      </visual>
      <sensor name="camera" type="camera">
        <pose>0.01 0 0 0 0 0</pose>
        <plugin name="camera_plugin" filename="libshisen_camera_plugin.so">
        </plugin>
        <camera>
          <horizontal_fov>1.047</horizontal_fov>
          <image>
            <width>320</width>
            <height>240</height>
          </image>
          <clip>
            <near>0.1</near>
            <far>100</far>
          </clip>
        </camera>
        <always_on>1</always_on>
        <update_rate>30</update_rate>
        <visualize>true</visualize>
      </sensor>
    </link>

    <link name="left_shoulder_link">
      <pose>0.026924 0.11869 1.39215 0 0 0</pose>
      <inertial>
        <mass>10.0</mass>
      </inertial>
      <collision name="left_shoulder_collision">
        <geometry>
          <mesh>
            <uri>model://dienen_robot/collisions/neck_collision.dae</uri>
          </mesh>
        </geometry>
      </collision>
      <visual name="left_shoulder_visual">
        <geometry>
          <mesh>
            <uri>model://dienen_robot/meshes/left_shoulder.dae</uri>
          </mesh>
        </geometry>
      </visual>
    </link>

    <link name="left_upper_arm_link">
      <pose>0.026924 0.201815 1.39175 0 0 0</pose>
      <inertial>
        <mass>10.0</mass>
      </inertial>
      <collision name="left_upper_arm_collision">
        <geometry>
          <mesh>
            <uri>model://dienen_robot/collisions/left_upper_arm_collision.dae</uri>
          </mesh>
        </geometry>
      </collision>
      <visual name="left_upper_arm_visual">
        <geometry>
          <mesh>
            <uri>model://dienen_robot/meshes/left_upper_arm.dae</uri>
          </mesh>
        </geometry>
      </visual>
    </link>

    <link name="left_lower_arm_link">
      <pose>0.026924 0.449757 1.34808 0 0 0</pose>
      <inertial>
        <mass>10.0</mass>
      </inertial>
      <collision name="left_lower_arm_collision">
        <geometry>
          <mesh>
            <uri>model://dienen_robot/collisions/left_lower_arm_collision.dae</uri>
          </mesh>
        </geometry>
      </collision>
      <visual name="left_lower_arm_visual">
        <geometry>
          <mesh>
            <uri>model://dienen_robot/meshes/left_lower_arm.dae</uri>
          </mesh>
        </geometry>
      </visual>
    </link>

    <link name="left_gripper_link">
      <pose>0.026924 0.693996 1.348 0 0 0</pose>
      <inertial>
        <mass>100.0</mass>
      </inertial>
      <collision name="left_gripper_collision">
        <geometry>
          <mesh>
            <uri>model://dienen_robot/collisions/left_gripper_collision.dae</uri>
          </mesh>
        </geometry>
      </collision>
      <visual name="left_gripper_visual">
        <geometry>
          <mesh>
            <uri>model://dienen_robot/meshes/left_gripper.dae</uri>
          </mesh>
        </geometry>
      </visual>
    </link>

    <link name="right_shoulder_link">
      <pose>0.026924 -0.11818 1.39215 0 0 0</pose>
      <inertial>
        <mass>10.0</mass>
      </inertial>
      <collision name="right_shoulder_collision">
        <geometry>
          <mesh>
            <uri>model://dienen_robot/collisions/right_shoulder_collision.dae</uri>
          </mesh>
        </geometry>
      </collision>
      <visual name="right_shoulder_visual">
        <geometry>
          <mesh>
            <uri>model://dienen_robot/meshes/right_shoulder.dae</uri>
          </mesh>
        </geometry>
      </visual>
    </link>

    <link name="right_upper_arm_link">
      <pose>0.026924 -0.201304 1.39175 0 0 0</pose>
      <inertial>
        <mass>10.0</mass>
      </inertial>
      <collision name="right_upper_arm_collision">
        <geometry>
          <mesh>
            <uri>model://dienen_robot/collisions/right_upper_arm_collision.dae</uri>
          </mesh>
        </geometry>
      </collision>
      <visual name="right_upper_arm_visual">
        <geometry>
          <mesh>
            <uri>model://dienen_robot/meshes/right_upper_arm.dae</uri>
          </mesh>
        </geometry>
      </visual>
    </link>

    <link name="right_lower_arm_link">
      <pose>0.026924 -0.449246 1.34808 0 0 0</pose>
      <inertial>
        <mass>10.0</mass>
      </inertial>
      <collision name="right_lower_arm_collision">
        <geometry>
          <mesh>
            <uri>model://dienen_robot/collisions/right_lower_arm_collision.dae</uri>
          </mesh>
        </geometry>
      </collision>
      <visual name="right_lower_arm_visual">
        <geometry>
          <mesh>
            <uri>model://dienen_robot/meshes/right_lower_arm.dae</uri>
          </mesh>
        </geometry>
      </visual>
    </link>

    <link name="right_gripper_link">
      <pose>0.026924 -0.693486 1.348 0 0 0</pose>
      <inertial>
        <mass>100.0</mass>
      </inertial>
      <collision name="right_gripper_collision">
        <geometry>
          <mesh>
            <uri>model://dienen_robot/collisions/right_gripper_collision.dae</uri>
          </mesh>
        </geometry>
      </collision>
      <visual name="right_gripper_visual">
        <geometry>
          <mesh>
            <uri>model://dienen_robot/meshes/right_gripper.dae</uri>
          </mesh>
        </geometry>
      </visual>
    </link>

    <joint name="upper_body_joint" type="fixed">
      <parent>lower_body_link</parent>
      <child>upper_body_link</child>
    </joint>

    <joint name="depth_camera_joint" type="fixed">
      <parent>upper_body_link</parent>
      <child>depth_camera_link</child>
    </joint>

    <joint name="neck_joint" type="fixed">
      <parent>upper_body_link</parent>
      <child>neck_link</child>
      <axis>
        <xyz>0 0 1</xyz>
      </axis>
    </joint>

    <joint name="head_joint" type="fixed">
      <parent>neck_link</parent>
      <child>head_link</child>
      <axis>
        <xyz>0 -1 0</xyz>
      </axis>
    </joint>

    <joint name="camera_joint" type="fixed">
      <parent>head_link</parent>
      <child>camera_link</child>
    </joint>

    <joint name="left_shoulder_joint" type="fixed">
      <parent>upper_body_link</parent>
      <child>left_shoulder_link</child>
      <axis>
        <xyz>0 -1 0</xyz>
      </axis>
    </joint>

    <joint name="left_upper_arm_joint" type="revolute">
      <parent>left_shoulder_link</parent>
      <child>left_upper_arm_link</child>
      <axis>
        <xyz>-1 0 0</xyz>
        <limit>
          <lower>-1.04719755</lower>
          <upper>1.04719755</upper>
        </limit>
      </axis>
    </joint>

    <joint name="left_lower_arm_joint" type="fixed">
      <parent>left_upper_arm_link</parent>
      <child>left_lower_arm_link</child>
      <axis>
        <xyz>-1 0 0</xyz>
      </axis>
    </joint>

    <joint name="left_gripper_joint" type="fixed">
      <parent>left_lower_arm_link</parent>
      <child>left_gripper_link</child>
      <axis>
        <xyz>-1 0 0</xyz>
      </axis>
    </joint>

    <joint name="right_shoulder_joint" type="fixed">
      <parent>upper_body_link</parent>
      <child>right_shoulder_link</child>
      <axis>
        <xyz>0 -1 0</xyz>
      </axis>
    </joint>

    <joint name="right_upper_arm_joint" type="revolute">
      <parent>right_shoulder_link</parent>
      <child>right_upper_arm_link</child>
      <axis>
        <xyz>1 0 0</xyz>
        <limit>
          <lower>-1.04719755</lower>
          <upper>1.04719755</upper>
        </limit>
      </axis>
    </joint>

    <joint name="right_lower_arm_joint" type="fixed">
      <parent>right_upper_arm_link</parent>
      <child>right_lower_arm_link</child>
      <axis>
        <xyz>1 0 0</xyz>
      </axis>
    </joint>

    <joint name="right_gripper_joint" type="fixed">
      <parent>right_lower_arm_link</parent>
      <child>right_gripper_link</child>
      <axis>
        <xyz>1 0 0</xyz>
      </axis>
    </joint>

  </model>
</sdf>
