<?xml version="1.0" ?>
<sdf version="1.5">
  <model name="dienen">
    <plugin name="navigation" filename="tosshin_sim/libnavigation_plugin.so">
    </plugin>
    <link name="body_link">
      <pose>0 0 0 0 0 0</pose>
      <inertial>
        <inertia>
          <ixx>0.058640</ixx>
          <ixy>0.000124</ixy>
          <ixz>0.000615</ixz>
          <iyy>0.058786</iyy>
          <iyz>0.000014</iyz>
          <izz>1.532440</izz>
        </inertia>
        <mass>2.234000</mass>
      </inertial>
      <collision name="body_collision">
        <pose>0 0 0.5 0 0 0</pose>
        <geometry>
          <cylinder>
            <radius>0.2</radius>
            <length>1.0</length>
          </cylinder>
        </geometry>
        <surface>
          <friction>
            <ode>
              <mu>10</mu>
              <mu2>10</mu2>
              <fdir1>0 0 0</fdir1>
              <slip1>0</slip1>
              <slip2>0</slip2>
            </ode>
          </friction>
        </surface>
      </collision>
      <visual name="lower_body_visual">
        <pose>0 0 0 0 0 0</pose>
        <geometry>
          <mesh>
            <uri>model://dienen_sim/dienen/meshes/lower_body.dae</uri>
          </mesh>
        </geometry>
      </visual>
      <visual name="upper_body_visual">
        <pose>0 0 0.747742 0 0 0</pose>
        <geometry>
          <mesh>
            <uri>model://dienen_sim/dienen/meshes/upper_body.dae</uri>
          </mesh>
        </geometry>
      </visual>
      <visual name="depth_camera_visual">
        <pose>0.036739 0 0.921716 0 0 0</pose>
        <geometry>
          <mesh>
            <uri>model://dienen_sim/dienen/meshes/depth_camera.dae</uri>
          </mesh>
        </geometry>
      </visual>
    </link>
    <link name="neck_link">
      <pose>-0.012158 0 0.957026 0 0 0</pose>
      <inertial>
        <inertia>
          <ixx>0.058640</ixx>
          <ixy>0.000124</ixy>
          <ixz>0.000615</ixz>
          <iyy>0.058786</iyy>
          <iyz>0.000014</iyz>
          <izz>1.532440</izz>
        </inertia>
        <mass>2.234000</mass>
      </inertial>
      <visual name="neck_visual">
        <pose>0 0 0 0 0 0</pose>
        <geometry>
          <mesh>
            <uri>model://dienen_sim/dienen/meshes/neck.dae</uri>
          </mesh>
        </geometry>
      </visual>
    </link>
    <link name="head_link">
      <pose>-0.008172 0 0.978114 0 0 0</pose>
      <inertial>
        <inertia>
          <ixx>0.058640</ixx>
          <ixy>0.000124</ixy>
          <ixz>0.000615</ixz>
          <iyy>0.058786</iyy>
          <iyz>0.000014</iyz>
          <izz>1.532440</izz>
        </inertia>
        <mass>2.234000</mass>
      </inertial>
      <sensor name="camera" type="camera">
        <pose>0.051501 0 0.133726 0 0 0</pose>
        <plugin name="camera" filename="shisen_sim/libcamera_plugin.so">
        </plugin>
        <camera>
          <horizontal_fov>1.047</horizontal_fov>
          <image>
            <width>320</width>
            <height>240</height>
          </image>
          <clip>
            <near>0.1</near>
            <far>100</far>
          </clip>
        </camera>
        <always_on>1</always_on>
        <update_rate>30</update_rate>
        <visualize>true</visualize>
      </sensor>
      <visual name="head_visual">
        <pose>0 0 0 0 0 0</pose>
        <geometry>
          <mesh>
            <uri>model://dienen_sim/dienen/meshes/head.dae</uri>
          </mesh>
        </geometry>
      </visual>
      <visual name="camera_visual">
        <pose>0.041501 0 0.133726 0 0 0</pose>
        <geometry>
          <mesh>
            <uri>model://dienen_sim/dienen/meshes/camera.dae</uri>
          </mesh>
        </geometry>
      </visual>
    </link>
    <joint name="neck_joint" type="revolute">
      <parent>body_link</parent>
      <child>neck_link</child>
      <axis>
        <xyz>0 0 1</xyz>
        <use_parent_model_frame>true</use_parent_model_frame>
      </axis>
    </joint>
    <joint name="head_joint" type="revolute">
      <parent>neck_link</parent>
      <child>head_link</child>
      <axis>
        <xyz>0 1 0</xyz>
        <use_parent_model_frame>true</use_parent_model_frame>
      </axis>
    </joint>
  </model>
</sdf>
