<?xml version="1.0" ?>
<sdf version="1.5">
  <model name="dienen">
    <plugin name='movement' filename='tosshin_sim/libmovement_plugin.so'>
    </plugin>
    <link name="base">
      <pose>0 0 0.5 0 0 0</pose>
      <inertial>
        <pose>0 0 0 0 0 0</pose>
        <inertia>
          <ixx>0.058640</ixx>
          <ixy>0.000124</ixy>
          <ixz>0.000615</ixz>
          <iyy>0.058786</iyy>
          <iyz>0.000014</iyz>
          <izz>1.532440</izz>
        </inertia>
        <mass>2.234000</mass>
      </inertial>
      <collision name="collision">
        <pose>0 0 0 0 0 0</pose>
        <geometry>
          <mesh>
            <uri>model://dienen_sim/dienen/meshes/base.dae</uri>
          </mesh>
        </geometry>
      </collision>
      <visual name="visual">
        <pose>0 0 0 0 0 0</pose>
        <geometry>
          <mesh>
            <uri>model://dienen_sim/dienen/meshes/base.dae</uri>
          </mesh>
        </geometry>
      </visual>
    </link>
    <link name="wheel_0">
      <pose>0.25 0.433013 0.3 1.5708 0 2.61799</pose>
      <inertial>
        <inertia>
          <ixx>0.001000</ixx>
          <ixy>0</ixy>
          <ixz>0</ixz>
          <iyy>0.001000</iyy>
          <iyz>0</iyz>
          <izz>0.001000</izz>
        </inertia>
        <mass>0.010000</mass>
      </inertial>
      <visual name="visual">
        <pose>0 0 0 0 0 0</pose>
        <geometry>
          <mesh>
            <uri>model://dienen_sim/dienen/meshes/wheel.dae</uri>
          </mesh>
        </geometry>
      </visual>
      <collision name="collision">
        <pose>0 0 0 0 0 0</pose>
        <geometry>
          <cylinder>
            <radius>0.31</radius>
            <length>0.13</length>
          </cylinder>
        </geometry>
        <surface>
          <friction>
            <ode>
              <mu>10</mu>
              <mu2>10</mu2>
              <fdir1>0 0 0</fdir1>
              <slip1>0</slip1>
              <slip2>0</slip2>
            </ode>
          </friction>
        </surface>
      </collision>
    </link>
    <link name="wheel_1">
      <pose>-0.5 0 0.3 1.5708 0 -1.5708</pose>
      <inertial>
        <inertia>
          <ixx>0.001000</ixx>
          <ixy>0</ixy>
          <ixz>0</ixz>
          <iyy>0.001000</iyy>
          <iyz>0</iyz>
          <izz>0.001000</izz>
        </inertia>
        <mass>0.010000</mass>
      </inertial>
      <visual name="visual">
        <pose>0 0 0 0 0 0</pose>
        <geometry>
          <mesh>
            <uri>model://dienen_sim/dienen/meshes/wheel.dae</uri>
          </mesh>
        </geometry>
      </visual>
      <collision name="collision">
        <pose>0 0 0 0 0 0</pose>
        <geometry>
          <cylinder>
            <radius>0.31</radius>
            <length>0.13</length>
          </cylinder>
        </geometry>
        <surface>
          <friction>
            <ode>
              <mu>10</mu>
              <mu2>10</mu2>
              <fdir1>0 0 0</fdir1>
              <slip1>0</slip1>
              <slip2>0</slip2>
            </ode>
          </friction>
        </surface>
      </collision>
    </link>
    <link name="wheel_2">
      <pose>0.25 -0.433013 0.3 1.5708 0 0.523599</pose>
      <inertial>
        <inertia>
          <ixx>0.001000</ixx>
          <ixy>0</ixy>
          <ixz>0</ixz>
          <iyy>0.001000</iyy>
          <iyz>0</iyz>
          <izz>0.001000</izz>
        </inertia>
        <mass>0.010000</mass>
      </inertial>
      <visual name="visual">
        <pose>0 0 0 0 0 0</pose>
        <geometry>
          <mesh>
            <uri>model://dienen_sim/dienen/meshes/wheel.dae</uri>
          </mesh>
        </geometry>
      </visual>
      <collision name="collision">
        <pose>0 0 0 0 0 0</pose>
        <geometry>
          <cylinder>
            <radius>0.31</radius>
            <length>0.13</length>
          </cylinder>
        </geometry>
        <surface>
          <friction>
            <ode>
              <mu>10</mu>
              <mu2>10</mu2>
              <fdir1>0 0 0</fdir1>
              <slip1>0</slip1>
              <slip2>0</slip2>
            </ode>
          </friction>
        </surface>
      </collision>
    </link>
    <joint name="wheel_0_joint" type="revolute">
      <parent>base</parent>
      <child>wheel_0</child>
      <axis>
        <xyz>0.5 0.866026 0</xyz>
        <use_parent_model_frame>true</use_parent_model_frame>
      </axis>
    </joint>
    <joint name="wheel_1_joint" type="revolute">
      <parent>base</parent>
      <child>wheel_1</child>
      <axis>
        <xyz>-1 0 0</xyz>
        <use_parent_model_frame>true</use_parent_model_frame>
      </axis>
    </joint>
    <joint name="wheel_2_joint" type="revolute">
      <parent>base</parent>
      <child>wheel_2</child>
      <axis>
        <xyz>0.5 -0.866026 0</xyz>
        <use_parent_model_frame>true</use_parent_model_frame>
      </axis>
    </joint>
  </model>
</sdf>
